Workbook
Name lstMembers: 'Paramètres'!$B$7:$B$14
Name lstCategories: 'Paramètres'!$E$7:$E$16

Sheet Lisez-moi
B2: Journal des heures
B3: Chaque membre note ses heures ; la synthèse compare le réalisé au prévu, par membre, catégorie et semaine.
B5: Mode d’emploi
B6: 1. | C6: Dans « Paramètres », saisissez le début du projet, les membres et leurs heures prévues, puis les catégories.
B7: 2. | C7: Dans « Journal », une ligne par séance de travail : date, membre, catégorie, description, heures (1,5 = une heure trente).
B8: 3. | C8: Le tableau s’agrandit seul quand vous écrivez sous la dernière ligne.
B9: 4. | C9: Lisez « Synthèse » : totaux, écarts au prévu et heures par semaine.
B11: Couleurs des cellules
B12: Paramètre | C12: À régler d’abord : date de début, membres, catégories…
B13: Saisie | C13: Cellules blanches : vos données, ligne par ligne.
B14: Calcul | C14: Cellules grises : calculées automatiquement, ne pas écraser.
B16: Bon à savoir
B17: · | C17: Les lignes livrées sont des exemples : effacez-les avant de commencer.
B18: · | C18: Repère : un crédit ECTS correspond à 25 à 30 heures de travail.
B20: Modèle Halo · police Helvetica · nuance : Mise en page → Thèmes.

Sheet Journal
A1: Date | B1: Membre | C1: Catégorie | D1: Description | E1: Heures | F1: Semaine
A2: 46279 | B2: Alex | C2: Gestion de projet | D2: Lancement du projet, rôles et calendrier | E2: 1.5 | F2: =IF(tJournal[[#This Row],[Date]]="","",WEEKNUM(tJournal[[#This Row],[Date]],21))
A3: 46279 | B3: Sam | C3: Gestion de projet | D3: Lancement du projet | E3: 1.5 | F3: =IF(tJournal[[#This Row],[Date]]="","",WEEKNUM(tJournal[[#This Row],[Date]],21))
A4: 46279 | B4: Noa | C4: Gestion de projet | D4: Lancement du projet | E4: 1.5 | F4: =IF(tJournal[[#This Row],[Date]]="","",WEEKNUM(tJournal[[#This Row],[Date]],21))
A5: 46281 | B5: Noa | C5: Analyse | D5: Entretiens avec le mandant | E5: 3 | F5: =IF(tJournal[[#This Row],[Date]]="","",WEEKNUM(tJournal[[#This Row],[Date]],21))
A6: 46283 | B6: Alex | C6: Documentation | D6: Cahier des charges, première version | E6: 2.5 | F6: =IF(tJournal[[#This Row],[Date]]="","",WEEKNUM(tJournal[[#This Row],[Date]],21))
A7: 46287 | B7: Sam | C7: Conception | D7: Maquettes des écrans principaux | E7: 4 | F7: =IF(tJournal[[#This Row],[Date]]="","",WEEKNUM(tJournal[[#This Row],[Date]],21))
A8: 46289 | B8: Noa | C8: Analyse | D8: Synthèse des besoins | E8: 2 | F8: =IF(tJournal[[#This Row],[Date]]="","",WEEKNUM(tJournal[[#This Row],[Date]],21))
A9: 46294 | B9: Alex | C9: Réunion | D9: Point hebdomadaire | E9: 1 | F9: =IF(tJournal[[#This Row],[Date]]="","",WEEKNUM(tJournal[[#This Row],[Date]],21))
A10: 46294 | B10: Sam | C10: Réunion | D10: Point hebdomadaire | E10: 1 | F10: =IF(tJournal[[#This Row],[Date]]="","",WEEKNUM(tJournal[[#This Row],[Date]],21))
A11: 46296 | B11: Sam | C11: Développement | D11: Mise en place du dépôt et de l’environnement | E11: 3.5 | F11: =IF(tJournal[[#This Row],[Date]]="","",WEEKNUM(tJournal[[#This Row],[Date]],21))

Sheet Synthèse
B2: Synthèse
B3: Calculée à partir du journal.
B4: Total des heures | C4: =SUM(tJournal[Heures])
B6: Par membre
B7: Membre | C7: Réalisé | D7: Prévu | E7: Écart | F7: Réalisé %
B8: =IF('Paramètres'!$B$7="","",'Paramètres'!$B$7) | C8: =IF(B8="","",SUMIFS(tJournal[Heures],tJournal[Membre],B8)) | D8: =IF(B8="","",'Paramètres'!$C$7) | E8: =IF(OR(B8="",D8=""),"",C8-D8) | F8: =IF(OR(B8="",N(D8)=0),"",C8/D8)
B9: =IF('Paramètres'!$B$8="","",'Paramètres'!$B$8) | C9: =IF(B9="","",SUMIFS(tJournal[Heures],tJournal[Membre],B9)) | D9: =IF(B9="","",'Paramètres'!$C$8) | E9: =IF(OR(B9="",D9=""),"",C9-D9) | F9: =IF(OR(B9="",N(D9)=0),"",C9/D9)
B10: =IF('Paramètres'!$B$9="","",'Paramètres'!$B$9) | C10: =IF(B10="","",SUMIFS(tJournal[Heures],tJournal[Membre],B10)) | D10: =IF(B10="","",'Paramètres'!$C$9) | E10: =IF(OR(B10="",D10=""),"",C10-D10) | F10: =IF(OR(B10="",N(D10)=0),"",C10/D10)
B11: =IF('Paramètres'!$B$10="","",'Paramètres'!$B$10) | C11: =IF(B11="","",SUMIFS(tJournal[Heures],tJournal[Membre],B11)) | D11: =IF(B11="","",'Paramètres'!$C$10) | E11: =IF(OR(B11="",D11=""),"",C11-D11) | F11: =IF(OR(B11="",N(D11)=0),"",C11/D11)
B12: =IF('Paramètres'!$B$11="","",'Paramètres'!$B$11) | C12: =IF(B12="","",SUMIFS(tJournal[Heures],tJournal[Membre],B12)) | D12: =IF(B12="","",'Paramètres'!$C$11) | E12: =IF(OR(B12="",D12=""),"",C12-D12) | F12: =IF(OR(B12="",N(D12)=0),"",C12/D12)
B13: =IF('Paramètres'!$B$12="","",'Paramètres'!$B$12) | C13: =IF(B13="","",SUMIFS(tJournal[Heures],tJournal[Membre],B13)) | D13: =IF(B13="","",'Paramètres'!$C$12) | E13: =IF(OR(B13="",D13=""),"",C13-D13) | F13: =IF(OR(B13="",N(D13)=0),"",C13/D13)
B14: =IF('Paramètres'!$B$13="","",'Paramètres'!$B$13) | C14: =IF(B14="","",SUMIFS(tJournal[Heures],tJournal[Membre],B14)) | D14: =IF(B14="","",'Paramètres'!$C$13) | E14: =IF(OR(B14="",D14=""),"",C14-D14) | F14: =IF(OR(B14="",N(D14)=0),"",C14/D14)
B15: =IF('Paramètres'!$B$14="","",'Paramètres'!$B$14) | C15: =IF(B15="","",SUMIFS(tJournal[Heures],tJournal[Membre],B15)) | D15: =IF(B15="","",'Paramètres'!$C$14) | E15: =IF(OR(B15="",D15=""),"",C15-D15) | F15: =IF(OR(B15="",N(D15)=0),"",C15/D15)
B17: Par catégorie
B18: Catégorie | C18: Heures | D18: Part
B19: =IF('Paramètres'!$E$7="","",'Paramètres'!$E$7) | C19: =IF(B19="","",SUMIFS(tJournal[Heures],tJournal[Catégorie],B19)) | D19: =IF(OR(B19="",$C$4=0),"",C19/$C$4)
B20: =IF('Paramètres'!$E$8="","",'Paramètres'!$E$8) | C20: =IF(B20="","",SUMIFS(tJournal[Heures],tJournal[Catégorie],B20)) | D20: =IF(OR(B20="",$C$4=0),"",C20/$C$4)
B21: =IF('Paramètres'!$E$9="","",'Paramètres'!$E$9) | C21: =IF(B21="","",SUMIFS(tJournal[Heures],tJournal[Catégorie],B21)) | D21: =IF(OR(B21="",$C$4=0),"",C21/$C$4)
B22: =IF('Paramètres'!$E$10="","",'Paramètres'!$E$10) | C22: =IF(B22="","",SUMIFS(tJournal[Heures],tJournal[Catégorie],B22)) | D22: =IF(OR(B22="",$C$4=0),"",C22/$C$4)
B23: =IF('Paramètres'!$E$11="","",'Paramètres'!$E$11) | C23: =IF(B23="","",SUMIFS(tJournal[Heures],tJournal[Catégorie],B23)) | D23: =IF(OR(B23="",$C$4=0),"",C23/$C$4)
B24: =IF('Paramètres'!$E$12="","",'Paramètres'!$E$12) | C24: =IF(B24="","",SUMIFS(tJournal[Heures],tJournal[Catégorie],B24)) | D24: =IF(OR(B24="",$C$4=0),"",C24/$C$4)
B25: =IF('Paramètres'!$E$13="","",'Paramètres'!$E$13) | C25: =IF(B25="","",SUMIFS(tJournal[Heures],tJournal[Catégorie],B25)) | D25: =IF(OR(B25="",$C$4=0),"",C25/$C$4)
B26: =IF('Paramètres'!$E$14="","",'Paramètres'!$E$14) | C26: =IF(B26="","",SUMIFS(tJournal[Heures],tJournal[Catégorie],B26)) | D26: =IF(OR(B26="",$C$4=0),"",C26/$C$4)
B27: =IF('Paramètres'!$E$15="","",'Paramètres'!$E$15) | C27: =IF(B27="","",SUMIFS(tJournal[Heures],tJournal[Catégorie],B27)) | D27: =IF(OR(B27="",$C$4=0),"",C27/$C$4)
B28: =IF('Paramètres'!$E$16="","",'Paramètres'!$E$16) | C28: =IF(B28="","",SUMIFS(tJournal[Heures],tJournal[Catégorie],B28)) | D28: =IF(OR(B28="",$C$4=0),"",C28/$C$4)
B31: Par semaine
B32: Semaine du | C32: N° | D32: =IF(B8="","",B8) | E32: =IF(B9="","",B9) | F32: =IF(B10="","",B10) | G32: =IF(B11="","",B11) | H32: =IF(B12="","",B12) | I32: Total
B33: ='Paramètres'!$C$4-WEEKDAY('Paramètres'!$C$4,3) | C33: =WEEKNUM(B33,21) | D33: =IF(D$32="","",SUMIFS(tJournal[Heures],tJournal[Membre],D$32,tJournal[Date],">="&$B33,tJournal[Date],"<"&$B33+7)) | E33: =IF(E$32="","",SUMIFS(tJournal[Heures],tJournal[Membre],E$32,tJournal[Date],">="&$B33,tJournal[Date],"<"&$B33+7)) | F33: =IF(F$32="","",SUMIFS(tJournal[Heures],tJournal[Membre],F$32,tJournal[Date],">="&$B33,tJournal[Date],"<"&$B33+7)) | G33: =IF(G$32="","",SUMIFS(tJournal[Heures],tJournal[Membre],G$32,tJournal[Date],">="&$B33,tJournal[Date],"<"&$B33+7)) | H33: =IF(H$32="","",SUMIFS(tJournal[Heures],tJournal[Membre],H$32,tJournal[Date],">="&$B33,tJournal[Date],"<"&$B33+7)) | I33: =SUMIFS(tJournal[Heures],tJournal[Date],">="&$B33,tJournal[Date],"<"&$B33+7)
B34: =B33+7 | C34: =WEEKNUM(B34,21) | D34: =IF(D$32="","",SUMIFS(tJournal[Heures],tJournal[Membre],D$32,tJournal[Date],">="&$B34,tJournal[Date],"<"&$B34+7)) | E34: =IF(E$32="","",SUMIFS(tJournal[Heures],tJournal[Membre],E$32,tJournal[Date],">="&$B34,tJournal[Date],"<"&$B34+7)) | F34: =IF(F$32="","",SUMIFS(tJournal[Heures],tJournal[Membre],F$32,tJournal[Date],">="&$B34,tJournal[Date],"<"&$B34+7)) | G34: =IF(G$32="","",SUMIFS(tJournal[Heures],tJournal[Membre],G$32,tJournal[Date],">="&$B34,tJournal[Date],"<"&$B34+7)) | H34: =IF(H$32="","",SUMIFS(tJournal[Heures],tJournal[Membre],H$32,tJournal[Date],">="&$B34,tJournal[Date],"<"&$B34+7)) | I34: =SUMIFS(tJournal[Heures],tJournal[Date],">="&$B34,tJournal[Date],"<"&$B34+7)
B35: =B34+7 | C35: =WEEKNUM(B35,21) | D35: =IF(D$32="","",SUMIFS(tJournal[Heures],tJournal[Membre],D$32,tJournal[Date],">="&$B35,tJournal[Date],"<"&$B35+7)) | E35: =IF(E$32="","",SUMIFS(tJournal[Heures],tJournal[Membre],E$32,tJournal[Date],">="&$B35,tJournal[Date],"<"&$B35+7)) | F35: =IF(F$32="","",SUMIFS(tJournal[Heures],tJournal[Membre],F$32,tJournal[Date],">="&$B35,tJournal[Date],"<"&$B35+7)) | G35: =IF(G$32="","",SUMIFS(tJournal[Heures],tJournal[Membre],G$32,tJournal[Date],">="&$B35,tJournal[Date],"<"&$B35+7)) | H35: =IF(H$32="","",SUMIFS(tJournal[Heures],tJournal[Membre],H$32,tJournal[Date],">="&$B35,tJournal[Date],"<"&$B35+7)) | I35: =SUMIFS(tJournal[Heures],tJournal[Date],">="&$B35,tJournal[Date],"<"&$B35+7)
B36: =B35+7 | C36: =WEEKNUM(B36,21) | D36: =IF(D$32="","",SUMIFS(tJournal[Heures],tJournal[Membre],D$32,tJournal[Date],">="&$B36,tJournal[Date],"<"&$B36+7)) | E36: =IF(E$32="","",SUMIFS(tJournal[Heures],tJournal[Membre],E$32,tJournal[Date],">="&$B36,tJournal[Date],"<"&$B36+7)) | F36: =IF(F$32="","",SUMIFS(tJournal[Heures],tJournal[Membre],F$32,tJournal[Date],">="&$B36,tJournal[Date],"<"&$B36+7)) | G36: =IF(G$32="","",SUMIFS(tJournal[Heures],tJournal[Membre],G$32,tJournal[Date],">="&$B36,tJournal[Date],"<"&$B36+7)) | H36: =IF(H$32="","",SUMIFS(tJournal[Heures],tJournal[Membre],H$32,tJournal[Date],">="&$B36,tJournal[Date],"<"&$B36+7)) | I36: =SUMIFS(tJournal[Heures],tJournal[Date],">="&$B36,tJournal[Date],"<"&$B36+7)
B37: =B36+7 | C37: =WEEKNUM(B37,21) | D37: =IF(D$32="","",SUMIFS(tJournal[Heures],tJournal[Membre],D$32,tJournal[Date],">="&$B37,tJournal[Date],"<"&$B37+7)) | E37: =IF(E$32="","",SUMIFS(tJournal[Heures],tJournal[Membre],E$32,tJournal[Date],">="&$B37,tJournal[Date],"<"&$B37+7)) | F37: =IF(F$32="","",SUMIFS(tJournal[Heures],tJournal[Membre],F$32,tJournal[Date],">="&$B37,tJournal[Date],"<"&$B37+7)) | G37: =IF(G$32="","",SUMIFS(tJournal[Heures],tJournal[Membre],G$32,tJournal[Date],">="&$B37,tJournal[Date],"<"&$B37+7)) | H37: =IF(H$32="","",SUMIFS(tJournal[Heures],tJournal[Membre],H$32,tJournal[Date],">="&$B37,tJournal[Date],"<"&$B37+7)) | I37: =SUMIFS(tJournal[Heures],tJournal[Date],">="&$B37,tJournal[Date],"<"&$B37+7)
B38: =B37+7 | C38: =WEEKNUM(B38,21) | D38: =IF(D$32="","",SUMIFS(tJournal[Heures],tJournal[Membre],D$32,tJournal[Date],">="&$B38,tJournal[Date],"<"&$B38+7)) | E38: =IF(E$32="","",SUMIFS(tJournal[Heures],tJournal[Membre],E$32,tJournal[Date],">="&$B38,tJournal[Date],"<"&$B38+7)) | F38: =IF(F$32="","",SUMIFS(tJournal[Heures],tJournal[Membre],F$32,tJournal[Date],">="&$B38,tJournal[Date],"<"&$B38+7)) | G38: =IF(G$32="","",SUMIFS(tJournal[Heures],tJournal[Membre],G$32,tJournal[Date],">="&$B38,tJournal[Date],"<"&$B38+7)) | H38: =IF(H$32="","",SUMIFS(tJournal[Heures],tJournal[Membre],H$32,tJournal[Date],">="&$B38,tJournal[Date],"<"&$B38+7)) | I38: =SUMIFS(tJournal[Heures],tJournal[Date],">="&$B38,tJournal[Date],"<"&$B38+7)
B39: =B38+7 | C39: =WEEKNUM(B39,21) | D39: =IF(D$32="","",SUMIFS(tJournal[Heures],tJournal[Membre],D$32,tJournal[Date],">="&$B39,tJournal[Date],"<"&$B39+7)) | E39: =IF(E$32="","",SUMIFS(tJournal[Heures],tJournal[Membre],E$32,tJournal[Date],">="&$B39,tJournal[Date],"<"&$B39+7)) | F39: =IF(F$32="","",SUMIFS(tJournal[Heures],tJournal[Membre],F$32,tJournal[Date],">="&$B39,tJournal[Date],"<"&$B39+7)) | G39: =IF(G$32="","",SUMIFS(tJournal[Heures],tJournal[Membre],G$32,tJournal[Date],">="&$B39,tJournal[Date],"<"&$B39+7)) | H39: =IF(H$32="","",SUMIFS(tJournal[Heures],tJournal[Membre],H$32,tJournal[Date],">="&$B39,tJournal[Date],"<"&$B39+7)) | I39: =SUMIFS(tJournal[Heures],tJournal[Date],">="&$B39,tJournal[Date],"<"&$B39+7)
B40: =B39+7 | C40: =WEEKNUM(B40,21) | D40: =IF(D$32="","",SUMIFS(tJournal[Heures],tJournal[Membre],D$32,tJournal[Date],">="&$B40,tJournal[Date],"<"&$B40+7)) | E40: =IF(E$32="","",SUMIFS(tJournal[Heures],tJournal[Membre],E$32,tJournal[Date],">="&$B40,tJournal[Date],"<"&$B40+7)) | F40: =IF(F$32="","",SUMIFS(tJournal[Heures],tJournal[Membre],F$32,tJournal[Date],">="&$B40,tJournal[Date],"<"&$B40+7)) | G40: =IF(G$32="","",SUMIFS(tJournal[Heures],tJournal[Membre],G$32,tJournal[Date],">="&$B40,tJournal[Date],"<"&$B40+7)) | H40: =IF(H$32="","",SUMIFS(tJournal[Heures],tJournal[Membre],H$32,tJournal[Date],">="&$B40,tJournal[Date],"<"&$B40+7)) | I40: =SUMIFS(tJournal[Heures],tJournal[Date],">="&$B40,tJournal[Date],"<"&$B40+7)
B41: =B40+7 | C41: =WEEKNUM(B41,21) | D41: =IF(D$32="","",SUMIFS(tJournal[Heures],tJournal[Membre],D$32,tJournal[Date],">="&$B41,tJournal[Date],"<"&$B41+7)) | E41: =IF(E$32="","",SUMIFS(tJournal[Heures],tJournal[Membre],E$32,tJournal[Date],">="&$B41,tJournal[Date],"<"&$B41+7)) | F41: =IF(F$32="","",SUMIFS(tJournal[Heures],tJournal[Membre],F$32,tJournal[Date],">="&$B41,tJournal[Date],"<"&$B41+7)) | G41: =IF(G$32="","",SUMIFS(tJournal[Heures],tJournal[Membre],G$32,tJournal[Date],">="&$B41,tJournal[Date],"<"&$B41+7)) | H41: =IF(H$32="","",SUMIFS(tJournal[Heures],tJournal[Membre],H$32,tJournal[Date],">="&$B41,tJournal[Date],"<"&$B41+7)) | I41: =SUMIFS(tJournal[Heures],tJournal[Date],">="&$B41,tJournal[Date],"<"&$B41+7)
B42: =B41+7 | C42: =WEEKNUM(B42,21) | D42: =IF(D$32="","",SUMIFS(tJournal[Heures],tJournal[Membre],D$32,tJournal[Date],">="&$B42,tJournal[Date],"<"&$B42+7)) | E42: =IF(E$32="","",SUMIFS(tJournal[Heures],tJournal[Membre],E$32,tJournal[Date],">="&$B42,tJournal[Date],"<"&$B42+7)) | F42: =IF(F$32="","",SUMIFS(tJournal[Heures],tJournal[Membre],F$32,tJournal[Date],">="&$B42,tJournal[Date],"<"&$B42+7)) | G42: =IF(G$32="","",SUMIFS(tJournal[Heures],tJournal[Membre],G$32,tJournal[Date],">="&$B42,tJournal[Date],"<"&$B42+7)) | H42: =IF(H$32="","",SUMIFS(tJournal[Heures],tJournal[Membre],H$32,tJournal[Date],">="&$B42,tJournal[Date],"<"&$B42+7)) | I42: =SUMIFS(tJournal[Heures],tJournal[Date],">="&$B42,tJournal[Date],"<"&$B42+7)
B43: =B42+7 | C43: =WEEKNUM(B43,21) | D43: =IF(D$32="","",SUMIFS(tJournal[Heures],tJournal[Membre],D$32,tJournal[Date],">="&$B43,tJournal[Date],"<"&$B43+7)) | E43: =IF(E$32="","",SUMIFS(tJournal[Heures],tJournal[Membre],E$32,tJournal[Date],">="&$B43,tJournal[Date],"<"&$B43+7)) | F43: =IF(F$32="","",SUMIFS(tJournal[Heures],tJournal[Membre],F$32,tJournal[Date],">="&$B43,tJournal[Date],"<"&$B43+7)) | G43: =IF(G$32="","",SUMIFS(tJournal[Heures],tJournal[Membre],G$32,tJournal[Date],">="&$B43,tJournal[Date],"<"&$B43+7)) | H43: =IF(H$32="","",SUMIFS(tJournal[Heures],tJournal[Membre],H$32,tJournal[Date],">="&$B43,tJournal[Date],"<"&$B43+7)) | I43: =SUMIFS(tJournal[Heures],tJournal[Date],">="&$B43,tJournal[Date],"<"&$B43+7)
B44: =B43+7 | C44: =WEEKNUM(B44,21) | D44: =IF(D$32="","",SUMIFS(tJournal[Heures],tJournal[Membre],D$32,tJournal[Date],">="&$B44,tJournal[Date],"<"&$B44+7)) | E44: =IF(E$32="","",SUMIFS(tJournal[Heures],tJournal[Membre],E$32,tJournal[Date],">="&$B44,tJournal[Date],"<"&$B44+7)) | F44: =IF(F$32="","",SUMIFS(tJournal[Heures],tJournal[Membre],F$32,tJournal[Date],">="&$B44,tJournal[Date],"<"&$B44+7)) | G44: =IF(G$32="","",SUMIFS(tJournal[Heures],tJournal[Membre],G$32,tJournal[Date],">="&$B44,tJournal[Date],"<"&$B44+7)) | H44: =IF(H$32="","",SUMIFS(tJournal[Heures],tJournal[Membre],H$32,tJournal[Date],">="&$B44,tJournal[Date],"<"&$B44+7)) | I44: =SUMIFS(tJournal[Heures],tJournal[Date],">="&$B44,tJournal[Date],"<"&$B44+7)
B45: =B44+7 | C45: =WEEKNUM(B45,21) | D45: =IF(D$32="","",SUMIFS(tJournal[Heures],tJournal[Membre],D$32,tJournal[Date],">="&$B45,tJournal[Date],"<"&$B45+7)) | E45: =IF(E$32="","",SUMIFS(tJournal[Heures],tJournal[Membre],E$32,tJournal[Date],">="&$B45,tJournal[Date],"<"&$B45+7)) | F45: =IF(F$32="","",SUMIFS(tJournal[Heures],tJournal[Membre],F$32,tJournal[Date],">="&$B45,tJournal[Date],"<"&$B45+7)) | G45: =IF(G$32="","",SUMIFS(tJournal[Heures],tJournal[Membre],G$32,tJournal[Date],">="&$B45,tJournal[Date],"<"&$B45+7)) | H45: =IF(H$32="","",SUMIFS(tJournal[Heures],tJournal[Membre],H$32,tJournal[Date],">="&$B45,tJournal[Date],"<"&$B45+7)) | I45: =SUMIFS(tJournal[Heures],tJournal[Date],">="&$B45,tJournal[Date],"<"&$B45+7)
...

Sheet Paramètres
B2: Paramètres
B3: Membres, heures prévues et catégories.
B4: Début du projet | C4: 46279
B6: Membre | C6: Heures prévues | E6: Catégories
B7: Alex | C7: 90 | E7: Analyse
B8: Sam | C8: 90 | E8: Conception
B9: Noa | C9: 90 | E9: Développement
E10: Tests
E11: Documentation
E12: Réunion
E13: Gestion de projet
E14: Présentation
